tests/mediumHard/mediumHard_98.in
15
o
3 B 101 STRA 578 694
9 B 102 AA 1900 571
10 B 103 AA 1089 890
5 S 104 GEGS 1677 611
9 C 102
13 B 108 AAO 759 301
6 B 109 AA 487 128
6 S 110 STRA 1000 425
3 S 111 GEGS 507 600
6 C 110
4 B 113 CONC 1109 965
2 S 115 HAHEOD 1073 717
5 S 116 AAM 1379 515
13 B 117 CAE 128 637
2 S 118 THRONE 707 496
10 S 119 AAC 1473 404
0 S 120 FEG 651 980
12 S 121 AA 1900 733
11 S 122 THRONE 1205 122
14 S 123 GORN 1989 639
6 S 124 THRONE 740 110
7 B 125 AAIN 436 582
6 C 109
2 S 127 HAHEOD 1160 559
6 C 109
7 C 125
4 B 130 GLIN 963 169
4 S 131 GEGS 1734 245
7 B 132 GEGS 1623 480
6 S 133 FEG 297 42
7 C 125
12 C 121
9 B 136 GLIN 1797 441
3 S 137 STRA 1585 456
1 S 138 DOOR 1321 310
0 C 120
5 S 140 AAC 1058 774
3 S 141 AAIN 145 208
6 S 142 BDD 955 299
1 C 138
1 B 144 AAN 536 858
4 B 145 CAE 1327 47
7 S 146 AAN 646 675
5 S 147 AAIC 1089 829
6 B 148 AAID 543 353
9 C 136
4 C 145
12 S 151 AAN 102 265
8 S 152 DOOR 149 600
7 B 153 GORN 427 984
10 B 154 STRIPE 444 149
9 S 155 AAIN 1791 812
1 B 156 AAID 354 644
9 C 136
4 B 158 AAO 1468 228
6 B 159 CONC 1116 586
12 C 151
0 S 161 STRA 241 957
4 B 162 GLIN 1213 225
12 S 163 AAIE 938 308
12 C 121
0 S 165 AAC 1510 463
11 S 166 AAIE 1051 557
12 B 167 THRONE 783 924
11 B 168 STRIPE 787 495
2 S 169 AA 1605 507
0 C 120
10 S 171 HAHEOD 1647 508
7 B 172 BDD 1153 907
12 C 121
8 C 152
0 B 175 GEGS 538 857
2 B 176 AA 1027 967
1 S 177 BDD 183 941
1 C 177
9 C 136
7 S 180 VIDE 1823 846
8 S 181 AA 528 991
0 C 175
11 B 183 THRONE 571 715
5 S 184 GORN 1295 795
12 C 151
13 C 117
10 B 187 AAID 1266 207
10 S 188 AAIC 1505 149
6 S 189 AAIC 1001 769
1 S 190 AAM 1391 681
9 B 191 AAM 670 435
1 S 192 AAIC 1655 131
6 C 133
0 C 120
1 B 195 STRIPE 186 262
7 C 146
12 B 197 VIDE 1197 319
1 S 198 AAIN 715 291
9 C 102
12 S 200 AAIN 1011 602
13 S 201 STRIPE 1600 602
14 C 123
0 C 161
12 C 167
0 C 161
10 B 206 GORN 1741 870
2 C 118
4 S 208 A 1549 521
7 B 209 AA 1571 37
2 S 210 AAID 1976 476
0 B 211 AAIC 782 519
11 B 212 BDD 1439 699
13 B 213 GLIN 1594 540
1 B 214 THRONE 1535 271
9 S 215 GLIN 739 407
3 S 216 STRA 982 28
12 S 217 AAN 784 969
13 C 108
11 C 166
14 C 123
7 C 153
12 S 222 CONC 1033 929
3 S 223 DOOR 361 100
4 S 224 GEGS 1994 243
7 C 180
2 B 226 AAC 1969 988
6 S 227 DOOR 1165 407
5 S 228 THRONE 525 431
5 C 228
2 B 230 THRONE 1435 325
6 S 231 AAIE 1338 736
0 S 232 DOOR 1032 583
5 C 140
2 C 118
8 C 181
11 C 168
6 S 237 AAIE 576 697
13 B 238 STRA 1801 668
2 B 239 AAC 875 644
3 C 141
9 C 136
0 S 242 AAIN 783 795
13 C 201
5 B 244 AAO 1340 171
1 B 245 AAM 1128 775
12 C 197
14 C 123
2 B 248 CONC 1441 146
0 B 249 BDD 1411 195
13 S 250 STRIPE 818 252
7 C 125
12 C 200
0 C 175
8 C 152
5 C 244
8 B 256 AAIN 151 30
13 B 257 STRIPE 1420 807
6 C 227
8 B 259 DOOR 1812 586
10 S 260 AAC 856 338
6 B 261 GEGS 1821 21
14 B 262 AAN 777 52
2 S 263 AAIE 605 250
4 C 131
13 S 265 AAO 513 473
5 S 266 AAO 1954 126
14 B 267 GEGS 902 391
2 S 268 AAIN 206 307
8 S 269 AAIN 1632 510
8 B 270 AA 1572 673
12 C 163
12 C 222
2 C 127
13 B 274 DOOR 1621 102
3 C 223
2 B 276 CONC 590 154
3 S 277 AAIE 746 972
2 C 115
12 B 279 AAID 374 268
5 C 266
0 S 281 A 1647 905
3 S 282 THRONE 580 273
3 C 101
14 C 262
14 C 262
11 B 286 STRIPE 1638 798
7 B 287 AAIC 346 216
12 C 151
8 S 289 AAM 1639 657
1 B 290 HAHEOD 824 899
1 B 291 AA 1553 910
14 S 292 AA 1516 440
3 S 293 AAID 1274 950
0 S 294 CAE 1366 111
1 C 214
0 S 296 CAE 749 978
3 S 297 HAHEOD 1438 365
1 S 298 DOOR 951 782
14 S 299 VIDE 587 726
8 B 300 STRA 464 391
7 S 301 AAN 1428 250
10 C 119
8 C 270
4 C 224
3 B 305 THRONE 1937 619
3 C 101
11 B 307 STRIPE 575 584
10 B 308 GORN 1656 824
2 B 309 GORN 1904 253
12 C 121
11 C 166
10 C 154
8 C 270
7 B 314 GORN 735 629
3 S 315 GORN 801 446
11 S 316 GORN 1714 421
11 S 317 AAIE 1268 688
6 C 231
8 C 300
6 S 320 A 1986 627
5 B 321 STRIPE 577 562
4 S 322 AAID 905 530
5 S 323 GORN 277 541
8 C 152
0 B 325 AAIE 105 211
8 B 326 GORN 1331 970
5 B 327 GORN 1317 326
13 S 328 STRIPE 1083 96
7 S 329 THRONE 551 494
12 B 330 GLIN 1999 50
10 B 331 VIDE 1813 738
3 S 332 GORN 273 553
10 S 333 GLIN 575 348
9 B 334 THRONE 1400 601
10 S 335 GEGS 1014 172
0 S 336 AA 1920 62
10 C 333
8 B 338 GEGS 1306 821
7 C 301
7 S 340 CONC 147 896
8 S 341 AAIE 423 632
4 C 162
0 B 343 AAID 1929 839
11 S 344 AA 353 274
14 C 262
5 S 346 STRA 1186 260
13 C 274
4 S 348 GORN 1067 965
6 C 142
3 C 137
11 C 166
0 B 352 AAC 305 747
7 B 353 HAHEOD 390 887
9 C 191
4 S 355 AAN 467 24
5 B 356 GLIN 1590 716
4 S 357 THRONE 1934 703
13 B 358 GLIN 789 880
1 S 359 AAIE 1492 847
13 S 360 THRONE 601 268
10 C 331
9 B 362 AAIN 1507 628
2 C 239
12 C 217
2 S 365 HAHEOD 1235 435
1 C 291
6 S 367 BDD 305 803
7 S 368 AAN 647 824
7 S 369 AAIC 225 700
10 B 370 AAID 742 562
0 S 371 VIDE 1037 788
0 S 372 DOOR 1411 453
5 B 373 HAHEOD 994 126
13 S 374 AAIE 1866 757
7 S 375 GLIN 1583 878
12 B 376 GLIN 690 940
11 B 377 FEG 1941 112
8 S 378 GORN 166 352
3 S 379 AAC 722 672
1 C 192
10 C 171
0 C 296
8 S 383 GLIN 959 416
2 B 384 BDD 894 565
11 S 385 AAO 1838 275
8 B 386 GEGS 1490 775
2 S 387 STRA 1902 729
3 C 101
1 C 198
10 B 390 CONC 1382 694
5 C 184
8 S 392 AAC 259 102
12 C 167
3 C 315
2 B 395 GORN 1227 241
8 S 396 THRONE 553 161
9 S 397 DOOR 1705 575
13 S 398 CONC 1742 490
13 B 399 AAIC 1288 797
11 C 377
1 S 401 AAM 1148 446
8 C 396
8 B 403 AA 1430 71
4 S 404 STRA 989 473
9 S 405 GORN 1165 975
9 B 406 AAIN 1114 87
5 B 407 BDD 961 374
11 S 408 STRA 333 804
6 C 159
14 S 410 AAIE 1094 267
10 C 335
0 S 412 AAN 1639 912
14 C 267
10 B 414 GLIN 628 75
8 C 403
12 B 416 GORN 1797 897
3 C 277
7 S 418 AAC 1602 620
1 C 401
8 C 386
4 B 421 AAID 1535 165
3 B 422 STRA 161 384
12 S 423 AAM 1181 297
12 C 376
12 B 425 CAE 335 503
4 C 357
6 C 261
12 B 428 THRONE 1574 119
9 B 429 GORN 1026 888
14 S 430 AAIC 1778 745
12 S 431 AAIE 1956 589
8 B 432 AAM 1514 663
10 B 433 GLIN 385 45
14 S 434 DOOR 1337 434
12 S 435 AAM 428 346
2 C 115
3 S 437 GORN 1753 990
0 S 438 A 886 570
12 B 439 GEGS 1246 739
10 B 440 AA 507 248
8 C 341
6 S 442 AAIC 991 168
0 S 443 STRIPE 190 665
11 S 444 AAM 1475 476
5 S 445 STRA 1609 84
2 C 384
6 B 447 FEG 1199 254
10 B 448 CAE 701 541
1 B 449 GORN 1975 491
10 S 450 AAIN 835 90
0 S 451 AA 1238 934
7 B 452 AAIC 1244 924
7 S 453 AAC 872 784
7 S 454 CAE 161 119
13 B 455 AAIE 276 294
1 S 456 GLIN 1757 900
4 S 457 CONC 1105 905
8 C 152
2 C 387
7 C 287
2 B 461 AA 703 588
6 S 462 AAM 1051 988
9 C 155
12 C 151
11 C 316
7 S 466 AAC 1793 834
6 C 148
4 C 208
4 C 130
11 S 470 AAO 976 938
6 C 442
3 B 472 GORN 991 681
5 S 473 AAIN 451 864
4 B 474 AA 1676 943
1 C 359
13 B 476 GEGS 1208 25
12 S 477 GORN 1220 889
11 B 478 FEG 686 45
2 B 479 CAE 1623 878
5 S 480 STRA 117 717
8 S 481 AAO 1078 297
1 B 482 BDD 663 102
7 C 172
12 C 423
6 B 485 CAE 1238 533
7 C 146
6 C 133
1 B 488 STRIPE 508 912
1 C 456
0 S 490 AAO 1761 274
1 C 198
7 C 375
3 C 216
0 S 494 AAIC 1896 550
0 S 495 GORN 1763 481
7 S 496 STRA 558 114
11 B 497 GEGS 886 228
0 B 498 CONC 1843 214
12 C 416
10 S 500 CAE 776 290
10 B 501 GEGS 1634 862
11 C 212
8 C 289
1 C 214
10 S 505 GEGS 133 664
4 B 506 AAN 915 425
10 C 206
9 B 508 CONC 1076 325
5 B 509 STRA 1647 45
7 B 510 AAM 864 877
12 S 511 A 1056 765
7 B 512 AAID 1256 108
10 B 513 AAIC 694 919
1 C 456
1 B 515 GORN 1387 62
4 B 516 AAM 728 856
1 S 517 STRA 1633 435
3 C 315
11 S 519 DOOR 678 362
14 S 520 CONC 288 957
12 B 521 AAN 1122 625
14 S 522 STRA 721 390
13 B 523 STRA 949 788
14 C 410
12 S 525 GORN 1617 471
1 C 192
9 C 136
9 S 528 CAE 1564 804
5 B 529 AAIC 1954 540
4 S 530 AAIE 1014 157
12 B 531 AAN 650 335
1 S 532 DOOR 1368 970
0 B 533 AAID 718 77
8 B 534 AAIC 1624 942
6 C 133
12 B 536 BDD 345 194
5 C 323
7 B 538 AA 1989 389
3 S 539 HAHEOD 1119 993
12 C 217
8 C 396
9 B 542 THRONE 536 736
12 C 423
5 S 544 CONC 693 576
8 C 386
1 B 546 HAHEOD 1953 533
3 B 547 HAHEOD 655 110
12 S 548 A 1328 982
5 B 549 DOOR 515 436
4 B 550 DOOR 1203 285
8 B 551 AAM 1659 515
5 B 552 HAHEOD 1453 533
2 S 553 AAIC 868 208
8 C 551
11 B 555 AAO 1568 605
7 S 556 AAO 1671 627
13 B 557 GLIN 1039 658
0 B 558 AAM 1675 951
11 C 555
7 S 560 AAIE 383 559
3 S 561 VIDE 733 356
11 S 562 CONC 1556 781
10 B 563 THRONE 821 611
7 B 564 AAC 988 286
