tests/mediumHard/mediumHard_99.in
15
o
3 S 101 GORN 553 490
4 B 102 AAM 1827 344
10 B 103 AAO 1999 226
2 S 105 AAC 1306 828
4 C 102
4 B 107 FEG 773 500
12 S 108 DOOR 652 758
10 S 109 GEGS 1085 740
1 B 111 AAN 1756 270
5 B 112 AAIN 1723 459
5 S 113 BDD 765 507
5 B 114 HAHEOD 602 467
9 S 115 HAHEOD 1541 699
1 S 116 AAO 225 898
11 S 117 AAID 1829 433
13 S 118 AAO 1213 535
10 B 119 AAIE 934 751
0 S 120 AAIE 1320 616
10 S 122 GORN 385 761
2 C 105
9 C 115
13 S 126 AAIN 1340 469
9 S 127 AAIE 1986 145
7 B 128 GEGS 1415 341
7 B 129 AAIC 827 575
5 S 130 GORN 1233 995
5 B 131 DOOR 321 999
0 S 132 THRONE 616 374
13 S 133 AAIN 1609 105
1 S 134 VIDE 1714 448
1 C 134
0 B 136 STRA 1625 561
3 C 101
12 S 138 VIDE 1021 453
6 B 139 STRA 500 396
0 C 120
6 C 139
0 S 142 GEGS 1547 757
11 B 143 THRONE 816 524
13 C 118
3 S 145 CONC 903 506
11 S 146 FEG 173 466
11 C 146
11 S 148 CONC 729 361
2 B 149 HAHEOD 1766 604
1 C 111
4 C 107
10 B 152 AAIN 1789 329
9 C 127
3 C 101
12 C 108
6 S 156 THRONE 428 516
4 C 107
7 S 158 AAID 1193 654
5 B 159 AAO 1983 112
13 C 133
14 S 162 HAHEOD 1534 189
11 S 163 AAO 1810 577
2 C 105
0 C 136
13 B 166 AAO 1542 285
5 C 159
6 C 156
2 S 169 AAC 220 138
4 B 170 AAM 675 316
5 S 171 AAIN 1364 347
10 B 172 GORN 1688 995
5 C 131
5 B 174 VIDE 386 765
11 C 148
5 C 171
1 C 134
0 S 178 CAE 416 697
0 B 179 AAO 1137 123
12 B 180 GORN 1859 347
12 S 181 BDD 1735 864
14 B 182 AAN 1843 319
5 C 130
2 C 105
8 B 185 CAE 878 287
9 S 186 BDD 1973 624
2 C 105
12 C 108
14 B 189 GORN 326 918
6 C 139
0 C 136
6 B 192 VIDE 477 911
5 S 193 BDD 1805 452
0 S 194 AAIN 122 302
13 B 195 AAIC 264 256
9 S 196 AAC 288 772
7 S 197 GEGS 1624 344
1 C 134
5 S 199 AAID 326 315
5 B 200 VIDE 411 414
5 C 193
5 C 114
14 C 162
11 S 204 AAIE 1088 595
11 S 205 THRONE 277 317
13 C 133
11 S 207 BDD 383 15
11 C 146
10 S 209 GEGS 1525 904
6 C 192
5 S 211 STRA 1824 498
14 C 182
0 B 213 AAID 931 431
14 C 189
4 S 215 AAIE 658 75
11 S 216 GORN 1673 499
12 S 217 CAE 1333 688
9 S 218 HAHEOD 1070 450
1 S 219 BDD 1622 49
3 B 220 AAIC 761 149
0 S 221 HAHEOD 1772 372
9 B 222 CAE 805 661
1 B 223 AAC 312 833
0 S 224 VIDE 468 335
11 C 146
13 B 226 AAN 1256 186
7 S 227 AAIC 1446 269
7 B 228 A 452 833
3 C 145
3 B 230 A 1804 35
4 S 231 GORN 1066 800
11 S 232 GORN 1318 643
4 C 102
0 B 234 VIDE 136 912
3 B 235 AAIN 1550 184
1 S 236 AAID 1768 759
14 S 237 AAIE 1199 987
12 B 238 AAIC 1837 885
10 C 119
13 B 240 AAIN 697 648
9 S 241 AAC 1129 264
2 B 242 STRA 269 878
14 B 243 CONC 1563 111
6 C 139
1 B 245 GORN 680 855
2 B 246 THRONE 1504 112
14 S 247 CAE 1143 426
0 B 248 AAID 297 530
10 B 249 STRIPE 329 428
11 C 204
8 C 185
9 C 115
2 C 149
6 C 156
3 B 255 AAO 1852 265
10 B 256 DOOR 1828 436
7 C 197
11 B 258 CAE 237 146
2 B 259 AAIE 156 971
9 C 127
5 C 112
3 S 262 GEGS 1596 564
3 C 255
7 S 264 AAC 122 626
3 S 265 STRA 1139 227
2 B 266 AA 1588 104
5 S 267 HAHEOD 863 901
8 S 268 AAIC 1028 742
12 S 269 GLIN 781 716
11 S 270 GEGS 1704 548
0 B 271 AAM 1454 819
4 C 102
9 B 273 STRA 1734 664
10 B 274 STRIPE 1295 926
1 S 275 AAID 1218 818
5 S 276 AAIN 795 388
11 C 270
10 C 152
4 C 107
6 B 280 AAIN 1420 181
9 C 273
8 S 282 AAN 843 339
6 C 280
5 S 284 AAIE 1904 646
8 B 285 AAIN 406 352
6 B 286 GLIN 1658 746
0 S 287 GEGS 1124 275
8 S 288 AAIN 1011 565
8 C 185
6 S 290 CONC 105 525
6 S 291 AAM 1410 901
8 C 285
3 B 293 AAID 621 971
14 C 189
13 B 295 AAIE 1147 663
7 B 296 AAN 731 868
13 C 126
11 B 298 GORN 1488 400
4 B 299 GORN 546 929
12 B 300 A 1818 521
7 S 301 A 1540 757
8 S 302 THRONE 723 711
3 B 303 CONC 1371 105
9 B 304 THRONE 1997 987
7 C 227
9 C 127
8 S 307 AAIN 1519 500
5 C 113
9 C 222
4 C 170
5 S 311 AAIN 1693 673
9 S 312 CONC 1403 726
5 B 313 VIDE 1181 21
11 B 314 AAIE 1652 302
5 S 315 AAID 1646 319
6 C 290
3 C 145
3 C 303
6 S 319 A 1153 623
3 C 303
13 C 295
5 B 322 AAM 210 664
10 S 323 GORN 772 971
6 S 324 FEG 542 90
4 S 325 AAN 1142 283
14 C 182
7 C 197
13 S 328 STRA 1657 171
6 C 192
3 B 330 THRONE 1543 317
8 S 331 STRIPE 549 83
11 S 332 GLIN 1222 696
4 B 333 AAIE 1279 44
0 S 334 A 1871 94
12 C 269
4 S 336 STRA 1282 304
4 S 337 AAID 965 424
14 S 338 AAM 900 603
8 S 339 STRA 105 607
13 S 340 GEGS 224 488
7 S 341 AAIN 740 650
10 B 342 AAID 1006 85
0 B 343 THRONE 107 454
4 S 344 GORN 915 159
12 B 345 AA 1798 364
8 S 346 FEG 717 678
10 C 109
14 B 348 STRIPE 583 445
10 S 349 AAN 442 284
4 S 350 AA 976 216
11 B 351 AAM 1105 137
13 B 352 DOOR 856 365
9 C 222
1 B 354 CAE 779 108
9 C 241
4 C 170
11 C 148
12 B 358 CONC 275 149
14 C 237
11 S 360 STRA 841 509
2 S 361 GORN 905 67
7 B 362 GORN 385 888
1 B 363 THRONE 1655 106
3 B 364 A 1583 230
8 S 365 AAC 1959 85
12 S 366 GEGS 1047 648
6 S 367 HAHEOD 1546 321
0 C 343
13 S 369 A 764 857
12 S 370 AAIE 591 354
7 C 128
9 S 372 GORN 413 25
0 C 194
2 B 374 GLIN 428 913
12 C 358
6 B 376 GORN 1549 394
3 B 377 AAID 410 896
6 B 378 CAE 1819 228
9 B 379 AAIC 1337 573
7 B 380 GORN 1399 795
9 B 381 A 1851 273
7 S 382 HAHEOD 1366 131
14 C 338
1 S 384 THRONE 1549 945
7 C 128
7 S 386 AAN 447 253
14 B 387 DOOR 1770 780
10 C 119
12 B 389 AAO 925 386
7 S 390 VIDE 538 17
13 B 391 AAIC 388 607
13 C 328
1 S 393 STRIPE 1657 624
1 B 394 BDD 524 150
13 C 352
4 B 396 AAIE 178 202
9 S 397 AAN 784 571
2 B 398 A 984 908
12 S 399 AAIC 1140 133
11 S 400 VIDE 575 45
13 B 401 VIDE 1849 421
1 C 116
13 S 403 GORN 1152 167
13 S 404 AAIC 1128 129
13 S 405 GORN 1034 371
8 B 406 THRONE 168 929
5 B 407 DOOR 417 284
12 S 408 FEG 1640 408
13 B 409 AAID 511 796
9 C 115
7 S 411 AAC 315 488
3 B 412 THRONE 1801 325
10 B 413 GEGS 1328 166
5 B 414 DOOR 1250 148
2 B 415 AAO 976 112
0 S 416 GORN 1119 134
0 B 417 AAID 337 498
10 C 209
10 S 419 BDD 575 277
10 B 420 GORN 1099 969
14 S 421 AA 1211 455
11 S 422 AAIE 1560 792
5 S 423 AAC 173 67
2 C 415
3 B 425 AAM 1639 985
10 C 119
11 C 148
2 S 428 BDD 1179 200
3 C 293
0 B 430 AAID 1656 156
8 C 339
4 C 231
6 B 433 BDD 1356 875
14 B 434 AAIE 515 569
2 C 428
3 C 230
4 C 336
4 B 438 BDD 1102 480
1 B 439 GLIN 288 523
8 S 440 AAIE 886 656
3 B 441 BDD 1335 421
8 C 346
7 B 443 AAM 1746 221
7 B 444 AA 154 712
6 B 445 CAE 1673 172
10 B 446 GORN 1853 916
11 C 232
4 C 215
4 S 449 FEG 1976 634
3 B 450 AAC 228 144
2 C 361
8 S 452 GEGS 233 228
8 C 365
9 B 454 GEGS 189 792
10 S 455 FEG 1686 165
4 S 456 VIDE 998 292
7 B 457 DOOR 1472 757
8 C 185
11 C 332
3 S 460 AAIN 1803 392
7 S 461 DOOR 535 131
1 C 111
1 B 463 AAO 1798 724
8 C 440
6 C 139
7 S 466 AAO 429 436
11 B 467 BDD 1698 848
3 B 468 AAM 1479 443
3 B 469 THRONE 1215 164
10 C 419
13 B 471 AAN 1775 337
4 S 472 AAIE 1888 776
13 C 295
8 B 474 FEG 1804 448
11 S 475 AAM 618 408
2 B 476 GORN 961 45
6 B 477 AAIC 202 721
13 C 403
7 B 479 STRIPE 859 441
2 S 480 AAN 703 656
3 B 481 AA 1906 675
2 S 482 GORN 1077 687
0 B 483 DOOR 1470 564
14 B 484 AAIE 400 123
0 S 485 AAID 1344 693
3 B 486 CAE 1195 33
7 C 466
10 B 488 AA 1540 339
12 C 370
9 B 490 GEGS 1651 685
4 C 344
11 C 143
2 B 493 AAC 922 126
13 B 494 AAC 1231 816
8 S 495 AAN 609 796
2 C 246
4 B 497 AAM 565 313
14 S 498 CAE 1441 638
9 B 499 AAN 565 405
14 B 500 AAIE 1553 302
5 C 311
2 B 502 BDD 1990 479
9 B 503 THRONE 1132 474
13 B 504 AAN 708 527
1 B 505 A 1074 841
14 C 387
0 B 507 FEG 861 17
13 S 508 DOOR 319 673
3 S 509 AAM 389 597
2 S 510 THRONE 197 133
9 S 511 CONC 1530 542
8 B 512 AAN 1119 662
10 S 513 AAM 1634 544
6 B 514 AAIE 755 34
10 S 515 GLIN 1364 85
12 S 516 VIDE 828 967
14 S 517 CAE 537 546
9 C 241
6 S 519 GORN 1083 267
1 C 394
6 S 521 HAHEOD 1143 508
14 B 522 AAN 1700 643
4 B 523 AAO 1287 946
2 C 502
9 S 525 A 1895 552
4 S 526 AAID 312 434
3 B 527 THRONE 364 928
10 C 209
11 C 148
9 B 530 AAIC 139 418
8 B 531 GEGS 1212 147
9 S 532 AAC 689 119
3 B 533 GORN 484 365
2 S 534 AAIC 440 245
4 S 535 HAHEOD 1308 811
4 B 536 AAIN 886 949
1 S 537 AAO 1723 178
2 C 493
7 S 539 GORN 1373 408
9 S 540 AAN 951 627
6 B 541 HAHEOD 465 625
3 C 145
4 B 543 AA 1217 370
10 S 544 AAM 486 202
13 C 403
6 B 546 AAO 1339 32
10 B 547 GLIN 482 91
6 S 548 AAID 913 115
0 C 248
0 B 550 AAIN 1540 948
7 C 457
9 B 552 GLIN 119 257
14 C 434
4 C 344
5 B 555 GORN 1241 539
9 C 222
4 B 557 AAN 1632 264
11 C 117
7 C 362
3 C 377
6 B 561 GLIN 1868 550
4 S 562 AAIC 426 425
1 B 563 AAID 1230 268
