tests/target.in
4
o
0 B 102 BBUC 223 391
3 S 103 ALTG^A 805 18
1 B 104 BC^A 1212 932
3 S 106 AHT 1092 492
0 S 108 AGM^E 1559 373
3 B 109 BAC^S 232 850
2 B 110 ATH^B 102 882
3 B 113 ARIS 1796 134
3 B 116 AAM^A 187 209
2 B 117 ABR 1957 183
1 B 118 APAM 300 334
3 S 121 AMBC 140 481
3 B 123 BKE 1721 931
1 S 124 ALIT 1049 912
1 S 125 AJX 1112 177
2 B 126 ASR 860 23
0 B 129 AWI 314 803
1 B 132 AB 1856 526
3 B 134 ASPN 1110 248
0 B 135 BIP^B 960 738
1 B 136 AHT 954 585
1 S 137 BKE 963 939
2 S 138 AOD 700 425
3 S 142 ALL^B 1092 156
0 S 143 BK 495 104
2 B 145 BBY 1706 728
3 S 146 BALL 1971 245
0 S 147 BC^A 1210 361
3 S 148 BAC^L 1335 678
1 B 149 AIG 1877 22
0 S 150 ARGO 855 844
3 S 151 BKDT 156 357
3 B 152 AEFC 359 771
2 B 153 BARK 1427 804
2 B 155 AL^A 1943 755
1 B 156 APTV^A 1918 689
1 S 158 ARR 1685 749
3 B 160 AQNU 1310 573
0 B 162 ANF 1621 10
0 S 163 ATTO 283 227
2 S 164 AJX 1057 545
2 B 165 AVB 409 302
2 B 166 BIPH 236 321
3 S 168 AMRC 1846 552
0 S 169 AYX 503 882
2 S 170 ABR^E 639 703
1 S 173 AXR 1688 311
1 B 174 BBLN 522 196
2 S 175 ALL 1254 922
1 S 176 BIP^A 1933 541
2 S 177 BLDR 1712 706
0 B 180 AUD 416 77
3 B 181 BCS 594 21
3 S 184 BHV 955 543
2 B 187 AMWL 1623 514
3 B 188 ARR^C 983 101
0 B 189 AMRC 1060 839
3 B 190 ARDC 1345 204
3 B 191 BLX 302 312
3 S 192 AFG 127 226
3 S 193 APAM 929 953
1 B 195 BBAR 1490 493
3 B 196 AMRC 1620 54
1 S 197 ATIP 563 366
1 S 202 BBD 1015 509
2 B 203 AEFC 1847 279
3 B 205 BML^J 869 591
0 S 208 AVTR 446 128
3 S 209 ARGO^A 540 495
2 S 210 BLK 528 210
2 B 212 BFLY 1115 708
0 S 214 BIO 1587 69
3 B 219 AGS 268 482
2 B 220 ABBV 1473 944
1 S 222 AIG 1104 447
2 B 224 ALG 851 981
2 B 225 BC^A 115 201
3 B 227 ANF 968 693
3 S 228 AMN 404 644
0 B 229 ASB^F 1500 342
3 B 230 ATGE 162 84
1 B 232 BAC^K 729 105
1 S 233 BLDR 794 173
3 B 234 BC^A 1970 861
0 S 235 ALL^H 1566 531
1 B 236 AJXA 670 137
2 B 238 AL^A 1082 807
2 S 241 BBY 1148 683
3 S 243 APLE 1757 827
0 S 244 BALL 1999 195
0 S 246 AGI 1017 380
1 B 247 BF/A 1492 214
2 B 248 ASPN 1886 320
1 S 249 BEST 1262 626
1 S 250 ANF 445 635
0 B 251 AOS 426 231
1 S 252 ACDI 1595 622
x
